/home/kmourat/GitHub/EDA_Miner_docs/EDA_miner_public/EDA_miner/__init__.py:docstring of EDA_miner.__init__:18: WARNING: Unexpected indentation.
/home/kmourat/GitHub/EDA_Miner_docs/EDA_miner_public/EDA_miner/__init__.py:docstring of EDA_miner.__init__:33: WARNING: Block quote ends without a blank line; unexpected unindent.
WARNING: autodoc: failed to import module 'menus' from module 'EDA_miner'; the following exception was raised:
Traceback (most recent call last):
  File "/home/kmourat/venv/lib/python3.6/site-packages/sphinx/ext/autodoc/importer.py", line 154, in import_module
    __import__(modname)
  File "/home/kmourat/GitHub/EDA_Miner_docs/EDA_miner_public/EDA_miner/menus.py", line 118, in <module>
    [Input('button_collapse', 'n_clicks')],)
  File "/home/kmourat/venv/lib/python3.6/site-packages/dash/dash.py", line 1018, in callback
    self._validate_callback(output, inputs, state)
  File "/home/kmourat/venv/lib/python3.6/site-packages/dash/dash.py", line 836, in _validate_callback
    raise exceptions.DuplicateCallbackOutput(msg)
dash.exceptions.DuplicateCallbackOutput: 
You have already assigned a callback to the output
with ID "sidebar_collapsible_button" and property "style". An output can only have
a single callback function. Try combining your inputs and
callback functions together into one function.


/home/kmourat/GitHub/EDA_Miner_docs/EDA_miner_public/EDA_miner/utils.py:docstring of EDA_miner.utils.create_dropdown:4: WARNING: Inline strong start-string without end-string.
WARNING: autodoc: failed to import module 'analyze_view' from module 'EDA_miner.apps'; the following exception was raised:
Traceback (most recent call last):
  File "/home/kmourat/venv/lib/python3.6/site-packages/sphinx/ext/autodoc/importer.py", line 154, in import_module
    __import__(modname)
  File "/home/kmourat/GitHub/EDA_Miner_docs/EDA_miner_public/EDA_miner/apps/analyze_view.py", line 53, in <module>
    [State("user_id", "children")])
  File "/home/kmourat/venv/lib/python3.6/site-packages/dash/dash.py", line 1018, in callback
    self._validate_callback(output, inputs, state)
  File "/home/kmourat/venv/lib/python3.6/site-packages/dash/dash.py", line 836, in _validate_callback
    raise exceptions.DuplicateCallbackOutput(msg)
dash.exceptions.DuplicateCallbackOutput: 
You have already assigned a callback to the output
with ID "model-content" and property "children". An output can only have
a single callback function. Try combining your inputs and
callback functions together into one function.


WARNING: autodoc: failed to import module 'data_view' from module 'EDA_miner.apps'; the following exception was raised:
Traceback (most recent call last):
  File "/home/kmourat/venv/lib/python3.6/site-packages/sphinx/ext/autodoc/importer.py", line 154, in import_module
    __import__(modname)
  File "/home/kmourat/GitHub/EDA_Miner_docs/EDA_miner_public/EDA_miner/apps/data_view.py", line 43, in <module>
    [State("user_id", "children")])
  File "/home/kmourat/venv/lib/python3.6/site-packages/dash/dash.py", line 1018, in callback
    self._validate_callback(output, inputs, state)
  File "/home/kmourat/venv/lib/python3.6/site-packages/dash/dash.py", line 836, in _validate_callback
    raise exceptions.DuplicateCallbackOutput(msg)
dash.exceptions.DuplicateCallbackOutput: 
You have already assigned a callback to the output
with ID "data-content" and property "children". An output can only have
a single callback function. Try combining your inputs and
callback functions together into one function.


WARNING: autodoc: failed to import module 'exploration_view' from module 'EDA_miner.apps'; the following exception was raised:
Traceback (most recent call last):
  File "/home/kmourat/venv/lib/python3.6/site-packages/sphinx/ext/autodoc/importer.py", line 154, in import_module
    __import__(modname)
  File "/home/kmourat/GitHub/EDA_Miner_docs/EDA_miner_public/EDA_miner/apps/exploration_view.py", line 54, in <module>
    [State("user_id", "children")])
  File "/home/kmourat/venv/lib/python3.6/site-packages/dash/dash.py", line 1018, in callback
    self._validate_callback(output, inputs, state)
  File "/home/kmourat/venv/lib/python3.6/site-packages/dash/dash.py", line 836, in _validate_callback
    raise exceptions.DuplicateCallbackOutput(msg)
dash.exceptions.DuplicateCallbackOutput: 
You have already assigned a callback to the output
with ID "visuals-content" and property "children". An output can only have
a single callback function. Try combining your inputs and
callback functions together into one function.


/home/kmourat/GitHub/EDA_Miner_docs/EDA_miner_public/EDA_miner/apps/analyze/__init__.py:docstring of EDA_miner.apps.analyze:5: WARNING: Unexpected indentation.
/home/kmourat/GitHub/EDA_Miner_docs/EDA_miner_public/EDA_miner/apps/analyze/__init__.py:docstring of EDA_miner.apps.analyze:10: WARNING: Block quote ends without a blank line; unexpected unindent.
WARNING: autodoc: failed to import module 'Classification' from module 'EDA_miner.apps.analyze'; the following exception was raised:
Traceback (most recent call last):
  File "/home/kmourat/venv/lib/python3.6/site-packages/sphinx/ext/autodoc/importer.py", line 154, in import_module
    __import__(modname)
  File "/home/kmourat/GitHub/EDA_Miner_docs/EDA_miner_public/EDA_miner/apps/analyze/Classification.py", line 62, in <module>
    [State("user_id", "children")])
  File "/home/kmourat/venv/lib/python3.6/site-packages/dash/dash.py", line 1018, in callback
    self._validate_callback(output, inputs, state)
  File "/home/kmourat/venv/lib/python3.6/site-packages/dash/dash.py", line 836, in _validate_callback
    raise exceptions.DuplicateCallbackOutput(msg)
dash.exceptions.DuplicateCallbackOutput: 
You have already assigned a callback to the output
with ID "variable_choices_classification" and property "children". An output can only have
a single callback function. Try combining your inputs and
callback functions together into one function.


WARNING: autodoc: failed to import module 'Clustering' from module 'EDA_miner.apps.analyze'; the following exception was raised:
Traceback (most recent call last):
  File "/home/kmourat/venv/lib/python3.6/site-packages/sphinx/ext/autodoc/importer.py", line 154, in import_module
    __import__(modname)
  File "/home/kmourat/GitHub/EDA_Miner_docs/EDA_miner_public/EDA_miner/apps/analyze/Clustering.py", line 58, in <module>
    [State("user_id", "children")])
  File "/home/kmourat/venv/lib/python3.6/site-packages/dash/dash.py", line 1018, in callback
    self._validate_callback(output, inputs, state)
  File "/home/kmourat/venv/lib/python3.6/site-packages/dash/dash.py", line 836, in _validate_callback
    raise exceptions.DuplicateCallbackOutput(msg)
dash.exceptions.DuplicateCallbackOutput: 
You have already assigned a callback to the output
with ID "variable_choices_clustering" and property "children". An output can only have
a single callback function. Try combining your inputs and
callback functions together into one function.


WARNING: autodoc: failed to import module 'Econometrics' from module 'EDA_miner.apps.analyze'; the following exception was raised:
Traceback (most recent call last):
  File "/home/kmourat/venv/lib/python3.6/site-packages/sphinx/ext/autodoc/importer.py", line 154, in import_module
    __import__(modname)
  File "/home/kmourat/GitHub/EDA_Miner_docs/EDA_miner_public/EDA_miner/apps/analyze/Econometrics.py", line 55, in <module>
    [State("user_id", "children")])
  File "/home/kmourat/venv/lib/python3.6/site-packages/dash/dash.py", line 1018, in callback
    self._validate_callback(output, inputs, state)
  File "/home/kmourat/venv/lib/python3.6/site-packages/dash/dash.py", line 836, in _validate_callback
    raise exceptions.DuplicateCallbackOutput(msg)
dash.exceptions.DuplicateCallbackOutput: 
You have already assigned a callback to the output
with ID "variable_choices_econometrics" and property "children". An output can only have
a single callback function. Try combining your inputs and
callback functions together into one function.


WARNING: autodoc: failed to import module 'Model_Builder' from module 'EDA_miner.apps.analyze'; the following exception was raised:
Traceback (most recent call last):
  File "/home/kmourat/venv/lib/python3.6/site-packages/sphinx/ext/autodoc/importer.py", line 154, in import_module
    __import__(modname)
  File "/home/kmourat/GitHub/EDA_Miner_docs/EDA_miner_public/EDA_miner/apps/analyze/Model_Builder.py", line 173, in <module>
    [State("modify_option_dropdown", "options")])
  File "/home/kmourat/venv/lib/python3.6/site-packages/dash/dash.py", line 1018, in callback
    self._validate_callback(output, inputs, state)
  File "/home/kmourat/venv/lib/python3.6/site-packages/dash/dash.py", line 836, in _validate_callback
    raise exceptions.DuplicateCallbackOutput(msg)
dash.exceptions.DuplicateCallbackOutput: 
You have already assigned a callback to the output
with ID "data_holder" and property "children". An output can only have
a single callback function. Try combining your inputs and
callback functions together into one function.


WARNING: autodoc: failed to import module 'Pipelines' from module 'EDA_miner.apps.analyze'; the following exception was raised:
Traceback (most recent call last):
  File "/home/kmourat/venv/lib/python3.6/site-packages/sphinx/ext/autodoc/importer.py", line 154, in import_module
    __import__(modname)
  File "/home/kmourat/GitHub/EDA_Miner_docs/EDA_miner_public/EDA_miner/apps/analyze/Pipelines.py", line 69, in <module>
    [State("user_id", "children")])
  File "/home/kmourat/venv/lib/python3.6/site-packages/dash/dash.py", line 1018, in callback
    self._validate_callback(output, inputs, state)
  File "/home/kmourat/venv/lib/python3.6/site-packages/dash/dash.py", line 836, in _validate_callback
    raise exceptions.DuplicateCallbackOutput(msg)
dash.exceptions.DuplicateCallbackOutput: 
You have already assigned a callback to the output
with ID "variable_choices_pipeline" and property "children". An output can only have
a single callback function. Try combining your inputs and
callback functions together into one function.


WARNING: autodoc: failed to import module 'Regression' from module 'EDA_miner.apps.analyze'; the following exception was raised:
Traceback (most recent call last):
  File "/home/kmourat/venv/lib/python3.6/site-packages/sphinx/ext/autodoc/importer.py", line 154, in import_module
    __import__(modname)
  File "/home/kmourat/GitHub/EDA_Miner_docs/EDA_miner_public/EDA_miner/apps/analyze/Regression.py", line 56, in <module>
    [State("user_id", "children")])
  File "/home/kmourat/venv/lib/python3.6/site-packages/dash/dash.py", line 1018, in callback
    self._validate_callback(output, inputs, state)
  File "/home/kmourat/venv/lib/python3.6/site-packages/dash/dash.py", line 836, in _validate_callback
    raise exceptions.DuplicateCallbackOutput(msg)
dash.exceptions.DuplicateCallbackOutput: 
You have already assigned a callback to the output
with ID "variable_choices_regression" and property "children". An output can only have
a single callback function. Try combining your inputs and
callback functions together into one function.


/home/kmourat/GitHub/EDA_Miner_docs/EDA_miner_public/EDA_miner/apps/analyze/models/__init__.py:docstring of EDA_miner.apps.analyze.models:5: WARNING: Unexpected indentation.
/home/kmourat/GitHub/EDA_Miner_docs/EDA_miner_public/EDA_miner/apps/analyze/models/__init__.py:docstring of EDA_miner.apps.analyze.models:9: WARNING: Block quote ends without a blank line; unexpected unindent.
/home/kmourat/GitHub/EDA_Miner_docs/EDA_miner_public/EDA_miner/apps/data/__init__.py:docstring of EDA_miner.apps.data:5: WARNING: Unexpected indentation.
/home/kmourat/GitHub/EDA_Miner_docs/EDA_miner_public/EDA_miner/apps/data/__init__.py:docstring of EDA_miner.apps.data:9: WARNING: Block quote ends without a blank line; unexpected unindent.
WARNING: autodoc: failed to import module 'APIs' from module 'EDA_miner.apps.data'; the following exception was raised:
Traceback (most recent call last):
  File "/home/kmourat/venv/lib/python3.6/site-packages/sphinx/ext/autodoc/importer.py", line 154, in import_module
    __import__(modname)
  File "/home/kmourat/GitHub/EDA_Miner_docs/EDA_miner_public/EDA_miner/apps/data/APIs.py", line 56, in <module>
    [State("user_id", "children")])
  File "/home/kmourat/venv/lib/python3.6/site-packages/dash/dash.py", line 1018, in callback
    self._validate_callback(output, inputs, state)
  File "/home/kmourat/venv/lib/python3.6/site-packages/dash/dash.py", line 836, in _validate_callback
    raise exceptions.DuplicateCallbackOutput(msg)
dash.exceptions.DuplicateCallbackOutput: 
You have already assigned a callback to the output
with ID "api_login_form" and property "children". An output can only have
a single callback function. Try combining your inputs and
callback functions together into one function.


WARNING: autodoc: failed to import module 'Upload' from module 'EDA_miner.apps.data'; the following exception was raised:
Traceback (most recent call last):
  File "/home/kmourat/venv/lib/python3.6/site-packages/sphinx/ext/autodoc/importer.py", line 154, in import_module
    __import__(modname)
  File "/home/kmourat/GitHub/EDA_Miner_docs/EDA_miner_public/EDA_miner/apps/data/Upload.py", line 40, in <module>
    State("user_id", "children")])
  File "/home/kmourat/venv/lib/python3.6/site-packages/dash/dash.py", line 1018, in callback
    self._validate_callback(output, inputs, state)
  File "/home/kmourat/venv/lib/python3.6/site-packages/dash/dash.py", line 836, in _validate_callback
    raise exceptions.DuplicateCallbackOutput(msg)
dash.exceptions.DuplicateCallbackOutput: 
You have already assigned a callback to the output
with ID "output-data-upload" and property "children". An output can only have
a single callback function. Try combining your inputs and
callback functions together into one function.


WARNING: autodoc: failed to import module 'View' from module 'EDA_miner.apps.data'; the following exception was raised:
Traceback (most recent call last):
  File "/home/kmourat/venv/lib/python3.6/site-packages/sphinx/ext/autodoc/importer.py", line 154, in import_module
    __import__(modname)
  File "/home/kmourat/GitHub/EDA_Miner_docs/EDA_miner_public/EDA_miner/apps/data/View.py", line 101, in <module>
    [Input("api_choice", "value")])
  File "/home/kmourat/venv/lib/python3.6/site-packages/dash/dash.py", line 1018, in callback
    self._validate_callback(output, inputs, state)
  File "/home/kmourat/venv/lib/python3.6/site-packages/dash/dash.py", line 836, in _validate_callback
    raise exceptions.DuplicateCallbackOutput(msg)
dash.exceptions.DuplicateCallbackOutput: 
You have already assigned a callback to the output
with ID "dataset_name" and property "style". An output can only have
a single callback function. Try combining your inputs and
callback functions together into one function.


/home/kmourat/GitHub/EDA_Miner_docs/EDA_miner_public/EDA_miner/apps/data/data_utils/__init__.py:docstring of EDA_miner.apps.data.data_utils:6: WARNING: Unexpected indentation.
/home/kmourat/GitHub/EDA_Miner_docs/EDA_miner_public/EDA_miner/apps/data/data_utils/__init__.py:docstring of EDA_miner.apps.data.data_utils:10: WARNING: Block quote ends without a blank line; unexpected unindent.
/home/kmourat/GitHub/EDA_Miner_docs/EDA_miner_public/EDA_miner/apps/exploration/__init__.py:docstring of EDA_miner.apps.exploration:6: WARNING: Unexpected indentation.
/home/kmourat/GitHub/EDA_Miner_docs/EDA_miner_public/EDA_miner/apps/exploration/__init__.py:docstring of EDA_miner.apps.exploration:9: WARNING: Block quote ends without a blank line; unexpected unindent.
WARNING: autodoc: failed to import module 'Exploration' from module 'EDA_miner.apps.exploration'; the following exception was raised:
Traceback (most recent call last):
  File "/home/kmourat/venv/lib/python3.6/site-packages/sphinx/ext/autodoc/importer.py", line 154, in import_module
    __import__(modname)
  File "/home/kmourat/GitHub/EDA_Miner_docs/EDA_miner_public/EDA_miner/apps/exploration/Exploration.py", line 115, in <module>
    [State("user_id", "children")])
  File "/home/kmourat/venv/lib/python3.6/site-packages/dash/dash.py", line 1018, in callback
    self._validate_callback(output, inputs, state)
  File "/home/kmourat/venv/lib/python3.6/site-packages/dash/dash.py", line 836, in _validate_callback
    raise exceptions.DuplicateCallbackOutput(msg)
dash.exceptions.DuplicateCallbackOutput: 
                Multi output ..xvars_2d.options...yvars_2d.options...yvars_2d.multi.. contains an `Output` object
                that was already assigned.
                Duplicates:
                {'yvars_2d.multi', 'yvars_2d.options', 'xvars_2d.options'}
                

WARNING: autodoc: failed to import module 'Exploration3D' from module 'EDA_miner.apps.exploration'; the following exception was raised:
Traceback (most recent call last):
  File "/home/kmourat/venv/lib/python3.6/site-packages/sphinx/ext/autodoc/importer.py", line 154, in import_module
    __import__(modname)
  File "/home/kmourat/GitHub/EDA_Miner_docs/EDA_miner_public/EDA_miner/apps/exploration/Exploration3D.py", line 78, in <module>
    [State("user_id", "children")])
  File "/home/kmourat/venv/lib/python3.6/site-packages/dash/dash.py", line 1018, in callback
    self._validate_callback(output, inputs, state)
  File "/home/kmourat/venv/lib/python3.6/site-packages/dash/dash.py", line 836, in _validate_callback
    raise exceptions.DuplicateCallbackOutput(msg)
dash.exceptions.DuplicateCallbackOutput: 
                Multi output ..xvars_3d.options...yvars_3d.options...zvars_3d.options.. contains an `Output` object
                that was already assigned.
                Duplicates:
                {'zvars_3d.options', 'yvars_3d.options', 'xvars_3d.options'}
                

WARNING: autodoc: failed to import module 'KPIs' from module 'EDA_miner.apps.exploration'; the following exception was raised:
Traceback (most recent call last):
  File "/home/kmourat/venv/lib/python3.6/site-packages/sphinx/ext/autodoc/importer.py", line 154, in import_module
    __import__(modname)
  File "/home/kmourat/GitHub/EDA_Miner_docs/EDA_miner_public/EDA_miner/apps/exploration/KPIs.py", line 75, in <module>
    [State("user_id", "children")])
  File "/home/kmourat/venv/lib/python3.6/site-packages/dash/dash.py", line 1018, in callback
    self._validate_callback(output, inputs, state)
  File "/home/kmourat/venv/lib/python3.6/site-packages/dash/dash.py", line 836, in _validate_callback
    raise exceptions.DuplicateCallbackOutput(msg)
dash.exceptions.DuplicateCallbackOutput: 
                Multi output ..xvars_kpi.options...yvars_kpi.options...secondary_yvars_kpi.options.. contains an `Output` object
                that was already assigned.
                Duplicates:
                {'xvars_kpi.options', 'secondary_yvars_kpi.options', 'yvars_kpi.options'}
                

WARNING: autodoc: failed to import module 'Networks' from module 'EDA_miner.apps.exploration'; the following exception was raised:
Traceback (most recent call last):
  File "/home/kmourat/venv/lib/python3.6/site-packages/sphinx/ext/autodoc/importer.py", line 154, in import_module
    __import__(modname)
  File "/home/kmourat/GitHub/EDA_Miner_docs/EDA_miner_public/EDA_miner/apps/exploration/Networks.py", line 99, in <module>
    [State("user_id", "children")])
  File "/home/kmourat/venv/lib/python3.6/site-packages/dash/dash.py", line 1018, in callback
    self._validate_callback(output, inputs, state)
  File "/home/kmourat/venv/lib/python3.6/site-packages/dash/dash.py", line 836, in _validate_callback
    raise exceptions.DuplicateCallbackOutput(msg)
dash.exceptions.DuplicateCallbackOutput: 
                Multi output ..in_node.options...out_node.options.. contains an `Output` object
                that was already assigned.
                Duplicates:
                {'out_node.options', 'in_node.options'}
                

WARNING: autodoc: failed to import module 'PDF_report' from module 'EDA_miner.apps.exploration'; the following exception was raised:
Traceback (most recent call last):
  File "/home/kmourat/venv/lib/python3.6/site-packages/sphinx/ext/autodoc/importer.py", line 154, in import_module
    __import__(modname)
  File "/home/kmourat/GitHub/EDA_Miner_docs/EDA_miner_public/EDA_miner/apps/exploration/PDF_report.py", line 154, in <module>
    State("row1_header_input", "value")])
  File "/home/kmourat/venv/lib/python3.6/site-packages/dash/dash.py", line 1018, in callback
    self._validate_callback(output, inputs, state)
  File "/home/kmourat/venv/lib/python3.6/site-packages/dash/dash.py", line 836, in _validate_callback
    raise exceptions.DuplicateCallbackOutput(msg)
dash.exceptions.DuplicateCallbackOutput: 
                Multi output ..graph12.figure...graph21.figure...row1col1.children...header_text.children...row1_header_text.children.. contains an `Output` object
                that was already assigned.
                Duplicates:
                {'graph12.figure',
 'graph21.figure',
 'header_text.children',
 'row1_header_text.children',
 'row1col1.children'}
                

WARNING: autodoc: failed to import module 'TextVisualizations' from module 'EDA_miner.apps.exploration'; the following exception was raised:
Traceback (most recent call last):
  File "/home/kmourat/venv/lib/python3.6/site-packages/sphinx/ext/autodoc/importer.py", line 154, in import_module
    __import__(modname)
  File "/home/kmourat/GitHub/EDA_Miner_docs/EDA_miner_public/EDA_miner/apps/exploration/TextVisualizations.py", line 60, in <module>
    State("user_id", "children")])
  File "/home/kmourat/venv/lib/python3.6/site-packages/dash/dash.py", line 1018, in callback
    self._validate_callback(output, inputs, state)
  File "/home/kmourat/venv/lib/python3.6/site-packages/dash/dash.py", line 836, in _validate_callback
    raise exceptions.DuplicateCallbackOutput(msg)
dash.exceptions.DuplicateCallbackOutput: 
You have already assigned a callback to the output
with ID "wordcloud_img" and property "src". An output can only have
a single callback function. Try combining your inputs and
callback functions together into one function.


/home/kmourat/GitHub/EDA_Miner_docs/EDA_miner_public/EDA_miner/apps/exploration/graphs/__init__.py:docstring of EDA_miner.apps.exploration.graphs:5: WARNING: Unexpected indentation.
/home/kmourat/GitHub/EDA_Miner_docs/EDA_miner_public/EDA_miner/apps/exploration/graphs/__init__.py:docstring of EDA_miner.apps.exploration.graphs:12: WARNING: Block quote ends without a blank line; unexpected unindent.
/home/kmourat/GitHub/EDA_Miner_docs/EDA_miner_public/EDA_miner/apps/exploration/graphs/graphs3d.py:docstring of EDA_miner.apps.exploration.graphs.graphs3d.scatterplot3d:4: WARNING: Inline strong start-string without end-string.
/home/kmourat/GitHub/EDA_Miner_docs/EDA_miner_public/EDA_miner/apps/exploration/graphs/textviz.py:docstring of EDA_miner.apps.exploration.graphs.textviz.create_wordcloud:4: WARNING: Inline strong start-string without end-string.

Sphinx error:
master file /home/kmourat/GitHub/EDA_Miner_docs/EDA_miner_public/docs/source/contents.rst not found
make: *** [html] Error 2
cp: cannot stat './build/html/modules.html': No such file or directory
